<robot name="arm">
    <link name="world" />
    <joint name="base_joint" type="fixed">
        <origin xyz="0 0 0.046482" rpy="0 0 0 " />
        <parent link="world" />
        <child link="base" />
    </joint>
    <link name="base">
        <visual>
            <geometry>
                <mesh filename="model://adaptive_guide/meshes/Base Link.dae" />
            </geometry>
        </visual>
        <inertial>
            <mass value="4.642" />
            <inertia ixx="0.0758" iyy="0.1601" izz="0.1032" ixy="0.0004" ixz="-0.0537" iyz="0.0016" />
        </inertial>

    </link>
    <joint name="phantom_joint" type="fixed">
        <origin xyz="0.140843 0.04279 0.065668" rpy="1.57 0 1.57" />
        <parent link="base" />
        <child link="phantom" />
    </joint>
    <link name="phantom">
        <visual>
            <geometry>
                <mesh filename="model://adaptive_guide/meshes/Phantom.dae" />
            </geometry>
        </visual>

        <inertial>
            <mass value="2.078" />
            <inertia ixx="0.0087" iyy="0.0277" izz="0.0279" ixy="-0.0091" ixz="0.0" iyz="0.0" />
        </inertial>

    </link>
    <link name="link1">
        <visual>
            <geometry>
                <mesh filename="model://adaptive_guide/meshes/Link1.dae" />
            </geometry>
        </visual>

        <inertial>
            <mass value="0.568" />
            <inertia ixx="0.0122" iyy="0.0007" izz="0.0119" ixy="0.0" ixz="0.0002" iyz="-0.0016" />
        </inertial>

    </link>
    <link name="link2">
        <visual>
            <geometry>
                <mesh filename="model:///adaptive_guide/meshes/Link2.dae" />
            </geometry>
        </visual>

        <inertial>
            <mass value="0.204" />
            <inertia ixx="0.0003" iyy="0.0012" izz="0.0014" ixy="0.0002" ixz="0.0001" iyz="0.0" />
        </inertial>

    </link>
    <link name="link3">
        <visual>
            <geometry>
                <mesh filename="model://adaptive_guide/meshes/Link3.dae" />
            </geometry>
        </visual>
        <inertial>
            <mass value="0.025" />
            <inertia ixx="0.0" iyy="0.0" izz="0.0" ixy="0.0" ixz="0.0" iyz="0.0" />
        </inertial>

    </link>
    <link name="link4">
        <visual>
            <geometry>
                <mesh filename="model://adaptive_guide/meshes/Link4.dae" />
            </geometry>
        </visual>

        <inertial>
            <mass value="0.023" />
            <inertia ixx="0.0" iyy="0.0" izz="0.0" ixy="0.0" ixz="0.0" iyz="0.0" />
        </inertial>

    </link>
    <link name="EE" />

    <joint name="joint1" type="prismatic">
        <origin xyz="0.005 0 0" rpy="0 0 0 " />
        <limit lower="0" upper="0.100" effort="30.0" velocity="6" />
        <parent link="base" />
        <child link="link1" />
        <axis xyz="0 0 1" />
    </joint>
    <joint name="joint2" type="prismatic">
        <origin xyz="0.040132 0 0.0487525" rpy="1.57 0 1.57" />
        <limit lower="0" upper="0.100" effort="30.0" velocity="6" />
        <parent link="link1" />
        <child link="link2" />
        <axis xyz="0 1 0" />
    </joint>
    <joint name="joint3" type="prismatic">
        <origin xyz="-0.009758 0.0333375 0.045724" rpy="0 0 0 " />
        <limit lower="-0.160" upper="0" effort="30.0" velocity="6" />
        <parent link="link2" />
        <child link="link3" />
        <axis xyz="1 0 0" />
    </joint>
    <joint name="joint4" type="revolute">
        <origin xyz="-0.00025 0 0" rpy="0 0 0 " />
        <limit lower="-3" upper="3" effort="30.0" velocity="6" />
        <parent link="link3" />
        <child link="link4" />
        <axis xyz="1 0 0" />
    </joint>
    <joint name="joint_EE" type="fixed">
        <origin xyz="0.16 0 0" rpy="0 0 0 " effort="30.0" velocity="6" />
        <parent link="link4" />
        <child link="EE" />
    </joint>
</robot>